<?xml version="1.0" encoding="utf-8"?>
<!-- This URDF was automatically created by SolidWorks to URDF Exporter! Originally created by Stephen Brawner (brawner@gmail.com) 
     Commit Version: 1.6.0-4-g7f85cfe  Build Version: 1.6.7995.38578
     For more information, please see http://wiki.ros.org/sw_urdf_exporter -->
<robot
  name="diff_bot">

  <!-- The Base Link -->
  <link
    name="base_link">
    <inertial>
      <origin
        xyz="0.093917 -5.5511E-17 -0.055692"
        rpy="0 0 0" />
      <mass
        value="3.4689" />
      <inertia
        ixx="0.012207"
        ixy="-3.1988E-18"
        ixz="-0.00086716"
        iyy="0.025768"
        iyz="3.556E-20"
        izz="0.034797" />
    </inertial>
    <visual>
      <origin
        xyz="0 0 0"
        rpy="0 0 0" />
      <geometry>
        <mesh
          filename="package://diff_bot/meshes/base_link.STL" />
      </geometry>
      <material
        name="">
        <color
          rgba="1 1 1 1" />
      </material>
    </visual>
    <collision>
      <origin
        xyz="0 0 0"
        rpy="0 0 0" />
      <geometry>
        <mesh
          filename="package://diff_bot/meshes/base_link.STL" />
      </geometry>
    </collision>
  </link>
  
  <!-- The Right Wheel -->
  <link
    name="rt_whl">
    <inertial>
      <origin
        xyz="-3.4694E-18 0 0"
        rpy="0 0 0" />
      <mass
        value="0.18864" />
      <inertia
        ixx="0.00012828"
        ixy="-2.9912E-20"
        ixz="-4.7453E-40"
        iyy="0.00023743"
        iyz="1.7768E-37"
        izz="0.00012828" />
    </inertial>
    <visual>
      <origin
        xyz="0 0 0"
        rpy="0 0 0" />
      <geometry>
        <mesh
          filename="package://diff_bot/meshes/rt_whl.STL" />
      </geometry>
      <material
        name="">
        <color
          rgba="0.29804 0.29804 0.29804 1" />
      </material>
    </visual>
    <collision>
      <origin
        xyz="0 0 0"
        rpy="0 0 0" />
      <geometry>
        <mesh
          filename="package://diff_bot/meshes/rt_whl.STL" />
      </geometry>
    </collision>
  </link>
  
  <joint
    name="rt_whl_jnt"
    type="continuous">
    <origin
      xyz="0 0.1225 -0.05"
      rpy="0 0 0" />
    <parent
      link="base_link" />
    <child
      link="rt_whl" />
    <axis
      xyz="0 -1 0" />
  </joint>
  
  <!-- The Left Wheel -->
  <link
    name="lft_whl">
    <inertial>
      <origin
        xyz="5.8981E-17 2.7756E-17 0"
        rpy="0 0 0" />
      <mass
        value="0.18864" />
      <inertia
        ixx="0.00012828"
        ixy="-3.1324E-20"
        ixz="-4.7453E-40"
        iyy="0.00023743"
        iyz="1.7768E-37"
        izz="0.00012828" />
    </inertial>
    <visual>
      <origin
        xyz="0 0 0"
        rpy="0 0 0" />
      <geometry>
        <mesh
          filename="package://diff_bot/meshes/lft_whl.STL" />
      </geometry>
      <material
        name="">
        <color
          rgba="0.29804 0.29804 0.29804 1" />
      </material>
    </visual>
    <collision>
      <origin
        xyz="0 0 0"
        rpy="0 0 0" />
      <geometry>
        <mesh
          filename="package://diff_bot/meshes/lft_whl.STL" />
      </geometry>
    </collision>
  </link>
  
  <joint
    name="lft_whl_jnt"
    type="continuous">
    <origin
      xyz="0 -0.1225 -0.05"
      rpy="0 0 0" />
    <parent
      link="base_link" />
    <child
      link="lft_whl" />
    <axis
      xyz="0 -1 0" />
  </joint>
  
  <!-- The Castor joint -->
  <link
    name="cst">
    <inertial>
      <origin
        xyz="-2.0329E-06 0 0.0046193"
        rpy="0 0 0" />
      <mass
        value="0.50472" />
      <inertia
        ixx="2.0927E-08"
        ixy="5.5078E-24"
        ixz="6.0363E-12"
        iyy="2.3416E-08"
        iyz="4.7559E-24"
        izz="2.6073E-08" />
    </inertial>
    <visual>
      <origin
        xyz="0 0 0"
        rpy="0 0 0" />
      <geometry>
        <mesh
          filename="package://diff_bot/meshes/cst.STL" />
      </geometry>
      <material
        name="">
        <color
          rgba="0.79216 0.81961 0.93333 1" />
      </material>
    </visual>
    <collision>
      <origin
        xyz="0 0 0"
        rpy="0 0 0" />
      <geometry>
        <mesh
          filename="package://diff_bot/meshes/cst.STL" />
      </geometry>
    </collision>
  </link>
  
  <joint
    name="cst_jnt"
    type="fixed">
    <origin
      xyz="0.23793 0 -0.024623"
      rpy="0 0 0" />
    <parent
      link="base_link" />
    <child
      link="cst" />
    <axis
      xyz="0 0 0" />
  </joint>

  <!-- The Castor Wheel -->
  <link
    name="cst_whl">
    <inertial>
      <origin
        xyz="-8.621E-09 -2.899E-10 -4.7633E-09"
        rpy="0 0 0" />
      <mass
        value="0.826585" />
      <inertia
        ixx="9.6258E-08"
        ixy="-1.7013E-15"
        ixz="7.8648E-14"
        iyy="1.6326E-07"
        iyz="2.5172E-15"
        izz="9.6258E-08" />
    </inertial>
    <visual>
      <origin
        xyz="0 0 0"
        rpy="0 0 0" />
      <geometry>
        <mesh
          filename="package://diff_bot/meshes/cst_whl.STL" />
      </geometry>
      <material
        name="">
        <color
          rgba="0.79216 0.81961 0.93333 1" />
      </material>
    </visual>
    <collision>
      <origin
        xyz="0 0 0"
        rpy="0 0 0" />
      <geometry>
        <mesh
          filename="package://diff_bot/meshes/cst_whl.STL" />
      </geometry>
    </collision>
  </link>
  
  <joint
    name="cst_jnt_whl"
    type="continuous">
    <origin
      xyz="0 0 0.013756"
      rpy="0 0 0" />
    <parent
      link="cst" />
    <child
      link="cst_whl" />
    <axis
      xyz="0 1 0" />
  </joint>

  <!-- The Lidar -->
  <!--doesn't have to be a lidar. I will be adding many files with various sensors very soon-->
  <link
    name="lidar">
    <inertial>
      <origin
        xyz="0 0 -0.012713"
        rpy="0 0 0" />
      <mass
        value="0.15019" />
      <inertia
        ixx="0.00099875"
        ixy="2.7529E-21"
        ixz="2.757E-21"
        iyy="0.00099875"
        iyz="1.1401E-20"
        izz="0.0018451" />
    </inertial>
    <visual>
      <origin
        xyz="0 0 0"
        rpy="0 0 0" />
      <geometry>
        <mesh
          filename="package://diff_bot/meshes/lidar.STL" />
      </geometry>
      <material
        name="">
        <color
          rgba="0.52941 0.54902 0.54902 1" />
      </material>
    </visual>
    <collision>
      <origin
        xyz="0 0 0"
        rpy="0 0 0" />
      <geometry>
        <mesh
          filename="package://diff_bot/meshes/lidar.STL" />
      </geometry>
    </collision>
  </link>
  
  <joint
    name="lidar_jnt"
    type="continuous">
    <origin
      xyz="0.05 0 -0.125"
      rpy="0 0 0" />
    <parent
      link="base_link" />
    <child
      link="lidar" />
    <axis
      xyz="0 0 1" />
  </joint>

  <!-- Laser Plugin -->
  <gazebo reference="lidar">
    <sensor type="ray" name="head_hokuyo_sensor">
      <pose>0 0 0 0 0 0</pose>
      <visualize>true</visualize>
      <update_rate>40</update_rate>
      <ray>
        <scan>
          <horizontal>
            <samples>720</samples>
            <resolution>1</resolution>
            <min_angle>-3.141592</min_angle>
            <max_angle>3.141592</max_angle>
          </horizontal>
        </scan>
        <range>
          <min>0.10</min>
          <max>10.0</max>
          <resolution>0.01</resolution>
        </range>
        <noise>
          <type>gaussian</type>
          <mean>0.0</mean>
          <stddev>0.01</stddev>
        </noise>
      </ray>
      <plugin name="gazebo_ros_head_hokuyo_controller" filename="libgazebo_ros_laser.so">
        <topicName>/rrbot/laser/scan</topicName>
        <frameName>lidar</frameName>
      </plugin>
    </sensor>
  </gazebo>

  <!-- Differential Drive Plugin -->
  <gazebo>
    <plugin 
      name="differential_drive_controller" 
      filename="libgazebo_ros_diff_drive.so">
      <updateRate>10</updateRate>
      <leftJoint>lft_whl_jnt</leftJoint>
      <rightJoint>rt_whl_jnt</rightJoint>
      <wheelSeparation>0.2</wheelSeparation>
      <wheelDiameter>0.1</wheelDiameter>
      <wheelAcceleration>5.0</wheelAcceleration>
      <wheelTorque>20</wheelTorque>
      <commandTopic>cmd_vel</commandTopic>
      <odometryTopic>odom</odometryTopic>
      <odometryFrame>odom</odometryFrame>
      <robotBaseFrame>base_link</robotBaseFrame>
      <odometrySource>1</odometrySource>
      <publishWheelTF>true</publishWheelTF>
      <publishOdom>true</publishOdom>
      <publishWheelJointState>true</publishWheelJointState>
      <legacyMode>false</legacyMode>
    </plugin>
  </gazebo>

</robot>