<?xml version="1.0"?>
<robot xmlns:xacro="http://www.ros.org/wiki/xacro" >

    <link name="lidar">
        <inertial>
            <origin xyz="0 0 -0.012713" rpy="0 0 0" />
            <mass value="0.15019" />
            <inertia ixx="0.00099875" ixy="2.7529E-21" ixz="2.757E-21" iyy="0.00099875" iyz="1.1401E-20" izz="0.0018451" />
        </inertial>
        <visual>
            <origin xyz="0 0 0" rpy="0 0 0" />
            <geometry>
                <mesh filename="package://diff_bot/meshes/lidar.STL" />
            </geometry>
            <material name=""> 
                <color rgba="0.52941 0.54902 0.54902 1" />
            </material>
        </visual>
        <collision>
            <origin xyz="0 0 0" rpy="0 0 0" />
            <geometry>
                <mesh filename="package://diff_bot/meshes/lidar.STL" />
            </geometry>
        </collision>
    </link>
  
    <joint name="lidar_jnt"  type="continuous">
        <origin xyz="0.05 0 -0.125" rpy="0 0 0" />
        <parent link="base_link" />
        <child link="lidar" />
        <axis xyz="0 0 1" />
    </joint>

    <gazebo reference="lidar">
        <sensor type="ray" name="head_hokuyo_sensor">
            <pose>0 0 0 0 0 0</pose>
            <visualize>true</visualize>
            <update_rate>40</update_rate>
            <ray>
                <scan>
                    <horizontal>
                        <samples>720</samples>
                        <resolution>1</resolution>
                        <min_angle>-3.141592</min_angle>
                        <max_angle>3.141592</max_angle>
                    </horizontal>
                </scan>
                <range>
                    <min>0.10</min>
                    <max>10.0</max>
                    <resolution>0.01</resolution>
                </range>
                <noise>
                    <type>gaussian</type>
                    <mean>0.0</mean>
                    <stddev>0.01</stddev>
                </noise>
            </ray>
            <plugin name="gazebo_ros_head_hokuyo_controller" filename="libgazebo_ros_laser.so">
                <topicName>/rrbot/laser/scan</topicName>
                <frameName>lidar</frameName>
            </plugin>
        </sensor>
    </gazebo>

</robot>

